<?xml version="1.0"?>
<robot name="tobias">
    <!-- BASE -->
    <link name="base">
        <visual>
            <origin xyz="0 0 0" rpy="0 0 0"/>
            <geometry>
                <mesh filename="base.stl" scale="0.001 0.001 0.001"/>
            </geometry>
            <material name="white">
                <color rgba="1 1 1 1"/>
            </material>
        </visual>
        <collision>
            <origin xyz="0 0 0" rpy="0 0 0"/>
            <geometry>
                <mesh filename="base.stl" scale="0.001 0.001 0.001"/>
            </geometry>
        </collision>
        <inertial>
            <mass value="0.951"/>
            <origin xyz="0.0 0.0 0.0"/>
            <inertia ixx="0.012350" ixy="-0.0000023" ixz="-0.0000720" iyy="0.010280" iyz="-0.000001114" izz="0.01949"/>
        </inertial>
    </link>

    <!-- ATTACHMENTS -->
    <link name="fr_joint">
        <visual>
            <origin xyz="0.0361 -0.1161 -0.0250" rpy="0 0 0"/>
            <geometry>
                <mesh filename="fr_joint.stl" scale="0.001 0.001 0.001"/>
            </geometry>
            <material name="dark_gray">
                <color rgba="0.2 0.2 0.2 1"/>
            </material>
        </visual>
        <collision>
            <origin xyz="0.0361 -0.1161 -0.0250" rpy="0 0 0"/>
            <geometry>
                <mesh filename="fr_joint.stl" scale="0.001 0.001 0.001"/>
            </geometry>
        </collision>
        <inertial>
            <mass value="0.04"/>
            <origin xyz="-0.1105 0.0873 0.0014"/>
            <inertia ixx="0.0000338460" ixy="0.00000109684" ixz="0.00000449108" iyy="0.0000485951" iyz="0.000000101" izz="0.00003789"/>
        </inertial>
    </link>

    <link name="fl_joint">
        <visual>
            <origin xyz="0.0361 0.0571 -0.0250" rpy="0 0 0"/>
            <geometry>
                <mesh filename="fl_joint.stl" scale="0.001 0.001 0.001"/>
            </geometry>
            <material name="dark_gray">
                <color rgba="0.2 0.2 0.2 1"/>
            </material>
        </visual>
        <collision>
            <origin xyz="0.0361 0.0571 -0.0250" rpy="0 0 0"/>
            <geometry>
                <mesh filename="fl_joint.stl" scale="0.001 0.001 0.001"/>
            </geometry>
        </collision>
        <inertial>
            <mass value="0.04"/>
            <origin xyz="-0.1105 -0.0873 0.0014"/>
            <inertia ixx="0.0000338460" ixy="0.00000109684" ixz="0.00000449108" iyy="0.0000485951" iyz="0.000000101" izz="0.00003789"/>
        </inertial>
    </link>

    <link name="br_joint">
        <visual>
            <origin xyz="-0.1371 -0.1161 -0.0250" rpy="0 0 0"/>
            <geometry>
                <mesh filename="br_joint.stl" scale="0.001 0.001 0.001"/>
            </geometry>
            <material name="dark_gray">
                <color rgba="0.2 0.2 0.2 1"/>
            </material>
        </visual>
        <collision>
            <origin xyz="-0.1371 -0.1161 -0.0250" rpy="0 0 0"/>
            <geometry>
                <mesh filename="br_joint.stl" scale="0.001 0.001 0.001"/>
            </geometry>
        </collision>
        <inertial>
            <mass value="0.04"/>
            <origin xyz="0.1113 0.0873 0.0014"/>
            <inertia ixx="0.0000338460" ixy="0.00000109684" ixz="-0.00000449108" iyy="0.0000485951" iyz="-0.000000101" izz="0.00003789"/>
        </inertial>
    </link>

    <link name="bl_joint">
        <visual>
            <origin xyz="-0.1371 0.0571 -0.0250" rpy="0 0 0"/>
            <geometry>
                <mesh filename="bl_joint.stl" scale="0.001 0.001 0.001"/>
            </geometry>
            <material name="dark_gray">
                <color rgba="0.2 0.2 0.2 1"/>
            </material>
        </visual>
        <collision>
            <origin xyz="-0.1371 0.0571 -0.0250" rpy="0 0 0"/>
            <geometry>
                <mesh filename="bl_joint.stl" scale="0.001 0.001 0.001"/>
            </geometry>
        </collision>
        <inertial>
            <mass value="0.04"/>
            <origin xyz="0.1113 -0.0873 0.0014"/>
            <inertia ixx="0.0000338460" ixy="0.00000109684" ixz="-0.00000449108" iyy="0.0000485951" iyz="-0.000000101" izz="0.00003789"/>
        </inertial>
    </link>

    <!-- LEGS -->
    <link name="fr_leg">
        <visual>
            <origin xyz="0.01 0 0.0" rpy="0 1.57 3.14"/>
            <geometry>
                <mesh filename="fr_leg.stl" scale="0.001 0.001 0.001"/>
            </geometry>
            <material name="red">
                <color rgba="0.6 0.2 0.2 1"/>
            </material>
        </visual>
        <collision>
            <origin xyz="0.01 0 0.0" rpy="0 1.57 3.14"/>
            <geometry>
                <mesh filename="fr_leg.stl" scale="0.001 0.001 0.001"/>
            </geometry>
        </collision>
        <inertial>
            <mass value="0.2"/>
            <origin xyz="-0.1519 0.0867 -0.0056"/>
            <inertia ixx="0.000059187" ixy="-0.000000695" ixz="0.000000032" iyy="0.0001867" iyz="0.000000004" izz="0.0002084"/>
        </inertial>
    </link>

    <link name="fl_leg">
        <visual>
            <origin xyz="0.01 0 0.0" rpy="0 1.57 3.14"/>
            <geometry>
                <mesh filename="fl_leg.stl" scale="0.001 0.001 0.001"/>
            </geometry>
            <material name="red">
                <color rgba="0.6 0.2 0.2 1"/>
            </material>
        </visual>
        <collision>
            <origin xyz="0.01 0 0.0" rpy="0 1.57 3.14"/>
            <geometry>
                <mesh filename="fl_leg.stl" scale="0.001 0.001 0.001"/>
            </geometry>
        </collision>
        <inertial>
            <mass value="0.2"/>
            <origin xyz="-0.1519 -0.0867 -0.0056"/>
            <inertia ixx="0.000059187" ixy="-0.000000695" ixz="0.000000032" iyy="0.0001867" iyz="0.000000004" izz="0.0002084"/>
        </inertial>
    </link>

    <link name="br_leg">
        <visual>
            <origin xyz="-0.01 0 0.0" rpy="0 1.57 0"/>
            <geometry>
                <mesh filename="br_leg.stl" scale="0.001 0.001 0.001"/>
            </geometry>
            <material name="red">
                <color rgba="0.6 0.2 0.2 1"/>
            </material>
        </visual>
        <collision>
            <origin xyz="-0.01 0 0.0" rpy="0 1.57 0"/>
            <geometry>
                <mesh filename="br_leg.stl" scale="0.001 0.001 0.001"/>
            </geometry>
        </collision>
        <inertial>
            <mass value="0.2"/>
            <origin xyz="0.1527 0.0867 -0.0056"/>
            <inertia ixx="0.000059187" ixy="-0.000000695" ixz="-0.000000032" iyy="0.0001867" iyz="-0.000000004" izz="0.0002084"/>
        </inertial>
    </link>

    <link name="bl_leg">
        <visual>
            <origin xyz="-0.01 0 0.0" rpy="0 1.57 0"/>
            <geometry>
                <mesh filename="bl_leg.stl" scale="0.001 0.001 0.001"/>
            </geometry>
            <material name="red">
                <color rgba="0.6 0.2 0.2 1"/>
            </material>
        </visual>
        <collision>
            <origin xyz="-0.01 0 0.0" rpy="0 1.57 0"/>
            <geometry>
                <mesh filename="bl_leg.stl" scale="0.001 0.001 0.001"/>
            </geometry>
        </collision>
        <inertial>
            <mass value="0.2"/>
            <origin xyz="0.1527 -0.0867 -0.0056"/>
            <inertia ixx="0.000059187" ixy="-0.000000695" ixz="-0.000000032" iyy="0.0001867" iyz="-0.000000004" izz="0.0002084"/>
        </inertial>
    </link>

    <!-- FEET -->
    <link name="fr_foot">
        <visual>
            <origin xyz="0.232 -0.217 0.0786" rpy="0 0 0"/>
            <geometry>
                <mesh filename="fr_foot.stl" scale="0.001 0.001 0.001"/>
            </geometry>
            <material name="dark_gray">
                <color rgba="0.2 0.2 0.2 1"/>
            </material>
        </visual>
        <collision>
            <origin xyz="0.232 -0.217 0.0786" rpy="0 0 0"/>
            <geometry>
                <mesh filename="fr_foot.stl" scale="0.001 0.001 0.001"/>
            </geometry>
        </collision>
        <inertial>
            <mass value="0.06"/>
            <origin xyz="-0.2478 0.0863 -0.0478"/>
            <inertia ixx="0.00006136" ixy="-0.000000000002" ixz="0.000005862" iyy="0.00005758" iyz="0.0000000001" izz="0.00001390"/>
        </inertial>
    </link>

    <link name="fl_foot">
        <visual>
            <origin xyz="0.1735 -0.031 0.0965" rpy="0 0 0"/>
            <geometry>
                <mesh filename="fl_foot.stl" scale="0.001 0.001 0.001"/>
            </geometry>
            <material name="dark_gray">
                <color rgba="0.2 0.2 0.2 1"/>
            </material>
        </visual>
        <collision>
            <origin xyz="0.1735 -0.03 0.0965" rpy="0 0 0"/>
            <geometry>
                <mesh filename="fl_foot.stl" scale="0.001 0.001 0.001"/>
            </geometry>
        </collision>
        <inertial>
            <mass value="0.06"/>
            <origin xyz="-0.2478 -0.0863 -0.0478"/>
            <inertia ixx="0.00006136" ixy="-0.000000000002" ixz="0.000005862" iyy="0.00005758" iyz="0.0000000001" izz="0.00001390"/>
        </inertial>
    </link>

    <link name="br_foot">
        <visual>
            <origin xyz="-0.207 -0.2295 0.0636" rpy="0 0 0"/>
            <geometry>
                <mesh filename="br_foot.stl" scale="0.001 0.001 0.001"/>
            </geometry>
            <material name="dark_gray">
                <color rgba="0.2 0.2 0.2 1"/>
            </material>
        </visual>
        <collision>
            <origin xyz="-0.207 -0.2295 0.0636" rpy="0 0 0"/>
            <geometry>
                <mesh filename="br_foot.stl" scale="0.001 0.001 0.001"/>
            </geometry>
        </collision>
        <inertial>
            <mass value="0.06"/>
            <origin xyz="0.2486 0.0863 -0.0478"/>
            <inertia ixx="0.00006136" ixy="-0.000000000002" ixz="-0.000005862" iyy="0.00005758" iyz="-0.0000000001" izz="0.00001390"/>
        </inertial>
    </link>

    <link name="bl_foot">
        <visual>
            <origin xyz="-0.1555 -0.074 0.056" rpy="0 0 0"/>
            <geometry>
                <mesh filename="bl_foot.stl" scale="0.001 0.001 0.001"/>
            </geometry>
            <material name="dark_gray">
                <color rgba="0.2 0.2 0.2 1"/>
            </material>
        </visual>
        <collision>
            <origin xyz="-0.1555 -0.074 0.056" rpy="0 0 0"/>
            <geometry>
                <mesh filename="bl_foot.stl" scale="0.001 0.001 0.001"/>
            </geometry>
        </collision>
        <inertial>
            <mass value="0.06"/>
            <origin  xyz="0.2486 0.0863 -0.0478"/>
            <inertia ixx="0.00006136" ixy="-0.000000000002" ixz="-0.000005862" iyy="0.00005758" iyz="-0.0000000001" izz="0.00001390"/>
        </inertial>
    </link>

    <!-- BASE TO JOINT CONNECTIONS -->
    <joint name="joint_base_to_fr" type="revolute">
        <parent link="base"/>
        <child link="fr_joint"/>
        <origin xyz="-0.0361 0.1161 0.0250" rpy="0 0 0"/>
        <axis xyz="0 0 -1"/>
        <limit lower="0" upper="1.571" effort="1.667" velocity="0.5"/>
    </joint>

    <joint name="joint_base_to_fl" type="revolute">
        <parent link="base"/>
        <child link="fl_joint"/>
        <origin xyz="-0.0361 -0.0571 0.0250" rpy="0 0 0"/>
        <axis xyz="0 0 1"/>
        <limit lower="0" upper="1.571" effort="1.667" velocity="0.5"/>
    </joint>

    <joint name="joint_base_to_br" type="revolute">
        <parent link="base"/>
        <child link="br_joint"/>
        <origin xyz="0.1371 0.1161 0.0250" rpy="0 0 0"/>
        <axis xyz="0 0 1"/>
        <limit lower="0" upper="1.571" effort="1.667" velocity="0.5"/>
    </joint>

    <joint name="joint_base_to_bl" type="revolute">
        <parent link="base"/>
        <child link="bl_joint"/>
        <origin xyz="0.1371 -0.0571 0.0250" rpy="0 0 0"/>
        <axis xyz="0 0 -1"/>
        <limit lower="0" upper="1.571" effort="1.667" velocity="0.5"/>
    </joint>

    <!-- JOINT TO LEG CONNECTIONS -->
    <joint name="joint_to_fr" type="revolute">
        <parent link="fr_joint"/>
        <child link="fr_leg"/>
        <origin xyz="-0.0449 0 -0.008" rpy="0 0 0"/>
        <axis xyz="0 -1 0"/>
        <limit lower="-0.262" upper="1.047" effort="1.667" velocity="0.5"/>
    </joint>

    <joint name="joint_to_fl" type="revolute">
        <parent link="fl_joint"/>
        <child link="fl_leg"/>
        <origin xyz="-0.0449 0 -0.0088" rpy="0 0 0"/>
        <axis xyz="0 -1 0"/>
        <limit lower="-0.262" upper="1.047" effort="1.667" velocity="0.5"/>
    </joint>

    <joint name="joint_to_br" type="revolute">
        <parent link="br_joint"/>
        <child link="br_leg"/>
        <origin xyz="0.045 0 -0.0088" rpy="0 0 0"/>
        <axis xyz="0 1 0"/>
        <limit lower="-0.262" upper="1.047" effort="1.667" velocity="0.5"/>
    </joint>

    <joint name="joint_to_bl" type="revolute">
        <parent link="bl_joint"/>
        <child link="bl_leg"/>
        <origin xyz="0.045 0 -0.0088" rpy="0 0 0"/>
        <axis xyz="0 1 0"/>
        <limit lower="-0.262" upper="1.047" effort="1.667" velocity="0.5"/>
    </joint>

    <!-- LEG TO FOOT CONNECTIONS -->
    <joint name="fr_foot_joint" type="revolute">
        <parent link="fr_leg"/>
        <child link="fr_foot"/>
        <origin xyz="-0.113 0 -0.008" rpy="0 0 0"/>
        <axis xyz="0 1 0"/>
        <limit lower="-1.262" upper="1.047"/>
    </joint>

    <joint name="fl_foot_joint" type="revolute">
        <parent link="fl_leg"/>
        <child link="fl_foot"/>
        <origin xyz="-0.113 0 -0.008" rpy="0 0 0"/>
        <axis xyz="0 1 0"/>
        <limit lower="-1.262" upper="1.047"/>
    </joint>

    <joint name="br_foot_joint" type="revolute">
        <parent link="br_leg"/>
        <child link="br_foot"/>
        <origin xyz="0.113 0 -0.008" rpy="0 0 0"/>
        <axis xyz="0 -1 0"/>
        <limit lower="-1.262" upper="1.047"/>
    </joint>

    <joint name="bl_foot_joint" type="revolute">
        <parent link="bl_leg"/>
        <child link="bl_foot"/>
        <origin xyz="0.113 0 -0.008" rpy="0 0 0"/>
        <axis xyz="0 -1 0"/>
        <limit lower="-1.262" upper="1.047"/>
    </joint>

</robot>
